Workbook

Sheet Growth Rate Calculation
B5: Approach 1:
C7: 2013 | D7: =(C7+1) -> 2014 | E7: =(D7+1) -> 2015 | F7: =(E7+1) -> 2016 | G7: =(F7+1) -> 2017 | H7: =(G7+1) -> 2018 | I7: =(H7+1) -> 2019 | J7: =(I7+1) -> 2020 | K7: =(J7+1) -> 2021 | L7: =(K7+1) -> 2022
B8: Revenue From Operations [Gross] | C8: 6598.9 | D8: 7803.1 | E8: 8515.34 | F8: 8742.4 | G8: 9583.7 | H8: 9861.74 | I8: 10221.07 | J8: 9826.51 | K8: 10936.01 | L8: 12174.22
B9: Growth Rate | D9: =(D8-C8)/C8 -> 0.18248496 | E9: =(E8-D8)/D8 -> 0.091276544 | F9: =(F8-E8)/E8 -> 0.026664819 | G9: =(G8-F8)/F8 -> 0.096232156 | H9: =(H8-G8)/G8 -> 0.02901176 | I9: =(I8-H8)/H8 -> 0.036436775 | J9: =(J8-I8)/I8 -> -0.038602612 | K9: =(K8-J8)/J8 -> 0.11290886 | L9: =(L8-K8)/K8 -> 0.1132232
L11: Avg Growth Rate | M11: =AVERAGE(D9:L9) -> 0.072181828
B14: Approach 2:
B16: Segment wise
B18: REVENUE MIX | C18: fy 16 | D18: fy 17 | E18: fy 18 | F18: fy 19 | G18: fy 20 | H18: fy 21
B19: Household insecticides | C19: 2305 | D19: 2373 | E19: 2263 | F19: 2254 | G19: 2190 | H19: 2534
B20: Personal Wash | C20: 1590 | D20: 1562 | E20: 1802 | F20: 1892 | G20: 1776 | H20: 2047
B21: Hair Care | C21: 578 | D21: 602 | E21: 622 | F21: 673 | G21: 627 | H21: 642
B22: Others | C22: 360 | D22: 494 | E22: 599 | F22: 740 | G22: 789 | H22: 861
B23: Unbranded/Exports | C23: 221 | D23: 226 | E23: 270 | F23: 303 | G23: 292 | H23: 331
B26: GROWTH RATES | C26: fy 17 | D26: fy 18 | E26: fy 19 | F26: fy 20 | G26: fy 21 | I26: Average Growth Rate
B27: Household insecticides | C27: =(D19/C19)-1 -> 0.029501085 | D27: =(E19/D19)-1 -> -0.046354825 | E27: =(F19/E19)-1 -> -0.0039770217 | F27: =(G19/F19)-1 -> -0.028393966 | G27: =(H19/G19)-1 -> 0.15707763 | I27: =AVERAGE(C27:G27) -> 0.021570579
B28: Personal Wash | C28: =(D20/C20)-1 -> -0.017610063 | D28: =(E20/D20)-1 -> 0.15364917 | E28: =(F20/E20)-1 -> 0.049944506 | F28: =(G20/F20)-1 -> -0.061310782 | G28: =(H20/G20)-1 -> 0.15259009 | I28: =AVERAGE(C28:G28) -> 0.055452584
B29: Hair Care | C29: =(D21/C21)-1 -> 0.041522491 | D29: =(E21/D21)-1 -> 0.033222591 | E29: =(F21/E21)-1 -> 0.081993569 | F29: =(G21/F21)-1 -> -0.068350669 | G29: =(H21/G21)-1 -> 0.023923445 | I29: =AVERAGE(C29:G29) -> 0.022462286
B30: Others | C30: =(D22/C22)-1 -> 0.37222222 | D30: =(E22/D22)-1 -> 0.21255061 | E30: =(F22/E22)-1 -> 0.23539232 | F30: =(G22/F22)-1 -> 0.066216216 | G30: =(H22/G22)-1 -> 0.091254753 | I30: =AVERAGE(C30:G30) -> 0.19552722
B31: Unbranded/Exports | C31: =(D23/C23)-1 -> 0.022624434 | D31: =(E23/D23)-1 -> 0.19469027 | E31: =(F23/E23)-1 -> 0.12222222 | F31: =(G23/F23)-1 -> -0.03630363 | G31: =(H23/G23)-1 -> 0.13356164 | I31: =AVERAGE(C31:G31) -> 0.087358987
I32: =AVERAGE(I27:I31) -> 0.076474332

Sheet Schedules
B3: Fixed Assets Schedule - PPE
B5: Particulars | C5: 44621 | D5: 44256 | E5: 43891 | F5: 43525 | G5: 43160 | H5: 42795 | I5: 42430 | J5: 42064 | K5: 41699 | L5: 41334
B6: Opening Balance | C6: 1210.22 | D6: 1205.02 | E6: 1192.29 | F6: 1066.36 | G6: 942.58 | H6: 847.09 | I6: 558.11 | J6: 522.42 | K6: 502.13 | L6: 394.53
B7: (Less) Disposals | C7: 30.98 | D7: 17.41 | E7: 12.22 | F7: 12.69 | G7: 10.75 | H7: 5.67 | I7: 79.06 | J7: 22.43 | K7: 19.42 | L7: 5.17
B8: Add: Capital Expenditure | D8: =D9-D6+D7 -> 22.61 | E8: =E9-E6+E7 -> 24.95 | F8: =F9-F6+F7 -> 138.62 | G8: =G9-G6+G7 -> 134.53 | H8: =H9-H6+H7 -> 101.16 | I8: =I9-I6+I7 -> 368.04 | J8: =J9-J6+J7 -> 58.12 | K8: =K9-K6+K7 -> 39.71 | L8: =L9-L6+L7 -> 112.77
B9: Closing Balance | C9: 1274.91 | D9: 1210.22 | E9: 1205.02 | F9: 1192.29 | G9: 1066.36 | H9: 942.58 | I9: 847.09 | J9: 558.11 | K9: 522.42 | L9: 502.13
B10: D&A note5 | C10: ='Historical Financials'!C20 -> 209.93 | D10: ='Historical Financials'!D20 -> 203.85 | E10: ='Historical Financials'!E20 -> 197.28 | F10: ='Historical Financials'!F20 -> 169.98 | G10: ='Historical Financials'!G20 -> 155.68 | H10: ='Historical Financials'!H20 -> 141.57 | I10: ='Historical Financials'!I20 -> 100.63 | J10: ='Historical Financials'!J20 -> 90.78 | ... L10: ='Historical Financials'!L20 -> 77
B11: D&A as % of Opening Balance | C11: =C10/C6 -> 0.17346433 | D11: =D10/D6 -> 0.16916732 | E11: =E10/E6 -> 0.1654631 | F11: =F10/F6 -> 0.15940208 | G11: =G10/G6 -> 0.1651637 | H11: =H10/H6 -> 0.1671251 | I11: =I10/I6 -> 0.18030496 | J11: =J10/J6 -> 0.17376823 | ... L11: =L10/L6 -> 0.19516894
B12: Cap Ex as % of Opening Balance | C12: ='Free Cash Flows'!C14/C6 -> 0.079051743 | D12: =D8/D6 -> 0.018763174 | E12: =E8/E6 -> 0.020926117 | F12: =F8/F6 -> 0.12999362 | G12: =G8/G6 -> 0.14272529 | H12: =H8/H6 -> 0.1194206 | I12: =I8/I6 -> 0.6594399 | J12: =J8/J6 -> 0.11125148 | K12: =K8/K6 -> 0.079083106 | L12: =L8/L6 -> 0.28583378
B14: Growth in PPE | C14: =(C9/D9)-1 -> 0.053453091 | D14: =(D9/E9)-1 -> 0.0043152811 | E14: =(E9/F9)-1 -> 0.010676933 | F14: =(F9/G9)-1 -> 0.11809333 | G14: =(G9/H9)-1 -> 0.13132042 | H14: =(H9/I9)-1 -> 0.1127271 | I14: =(I9/J9)-1 -> 0.51778323 | J14: =(J9/K9)-1 -> 0.06831668 | K14: =(K9/L9)-1 -> 0.040407863
B16: Years | C16: Base (FY22) | D16: FY23E | E16: FY24E | F16: FY25E | G16: FY26E | H16: FY27E | I16: FY28E | J16: FY29E | K16: FY30E | L16: FY31E | M16: FY32E
B17: Predicted PPE (Closing Balance) | C17: =C9 -> 1274.91 | D17: =C17*(1+D18) -> 1462.9017 | E17: =D17*(1+E18) -> 1673.2209 | F17: =E17*(1+F18) -> 1907.7635 | G17: =F17*(1+G18) -> 2168.4974 | H17: =G17*(1+H18) -> 2457.4566 | I17: =H17*(1+I18) -> 2776.7339 | J17: =I17*(1+J18) -> 3128.4734 | K17: =J17*(1+K18) -> 3514.8616 | ... M17: =L17*(1+M18) -> 4400.4886
B18: Predicted Growth in PPE note 6 | D18: =AVERAGE(C14:K14)+0.03 -> 0.14745488 | E18: =D18*(1-0.025) -> 0.14376851 | F18: =E18*(1-0.025) -> 0.1401743 | G18: =F18*(1-0.025) -> 0.13666994 | H18: =G18*(1-0.025) -> 0.13325319 | I18: =H18*(1-0.025) -> 0.12992186 | J18: =I18*(1-0.025) -> 0.12667381 | K18: =J18*(1-0.025) -> 0.12350697 | L18: =K18*(1-0.025) -> 0.12041929 | M18: =L18*(1-0.025) -> 0.11740881
B22: Ratios
B23: Fiscal Year | C23: ='Historical Financials'!C4 -> 44621 | D23: ='Historical Financials'!D4 -> 44256 | E23: ='Historical Financials'!E4 -> 43891 | F23: ='Historical Financials'!F4 -> 43525 | G23: ='Historical Financials'!G4 -> 43160 | H23: ='Historical Financials'!H4 -> 42795 | I23: ='Historical Financials'!I4 -> 42430 | J23: ='Historical Financials'!J4 -> 42064 | ... L23: ='Historical Financials'!L4 -> 41334
B24: Revenue Growth | C24: =('Historical Financials'!C13/'Historical Financials'!D13)-1 -> 0.11450572 | D24: =('Historical Financials'!D13/'Historical Financials'!E13)-1 -> 0.1070118 | E24: =('Historical Financials'!E13/'Historical Financials'!F13)-1 -> -0.038376299 | F24: =('Historical Financials'!F13/'Historical Financials'!G13)-1 -> 0.047461415 | G24: =('Historical Financials'!G13/'Historical Financials'!H13)-1 -> 0.065032253 | H24: =('Historical Financials'!H13/'Historical Financials'!I13)-1 -> 0.098196004 | I24: =('Historical Financials'!I13/'Historical Financials'!J13)-1 -> 0.016719906 | J24: =('Historical Financials'!J13/'Historical Financials'!K13)-1 -> 0.091681539 | K24: =('Historical Financials'!K13/'Historical Financials'!L13)-1 -> 0.1837621
B25: Operating Margin | C25: =('Historical Financials'!C11-SUM('Historical Financials'!C15:C18,'Historical Financials'!C20))/'Historical Financials'!C13 -> 0.39521729 | D25: =('Historical Financials'!D11-SUM('Historical Financials'!D15:D18,'Historical Financials'!D20))/'Historical Financials'!D13 -> 0.4300778 | E25: =('Historical Financials'!E11-SUM('Historical Financials'!E15:E18,'Historical Financials'!E20))/'Historical Financials'!E13 -> 0.44228033 | F25: =('Historical Financials'!F11-SUM('Historical Financials'!F15:F18,'Historical Financials'!F20))/'Historical Financials'!F13 -> 0.4338076 | G25: =('Historical Financials'!G11-SUM('Historical Financials'!G15:G18,'Historical Financials'!G20))/'Historical Financials'!G13 -> 0.43773478 | H25: =('Historical Financials'!H11-SUM('Historical Financials'!H15:H18,'Historical Financials'!H20))/'Historical Financials'!H13 -> 0.42869207 | I25: =('Historical Financials'!I11-SUM('Historical Financials'!I15:I18,'Historical Financials'!I20))/'Historical Financials'!I13 -> 0.41278453 | J25: =('Historical Financials'!J11-SUM('Historical Financials'!J15:J18,'Historical Financials'!J20))/'Historical Financials'!J13 -> 0.4262865 | ... L25: =('Historical Financials'!L11-SUM('Historical Financials'!L15:L18,'Historical Financials'!L20))/'Historical Financials'!L13 -> 0.43066336
B26: Tax Rate | C26: ='Historical Financials'!C27/'Historical Financials'!C25 -> 0.1843683 | D26: ='Historical Financials'!D27/'Historical Financials'!D25 -> 0.19618626 | E26: ='Historical Financials'!E27/'Historical Financials'!E25 -> 0.21519786 | F26: ='Historical Financials'!F27/'Historical Financials'!F25 -> 0.2004605 | G26: ='Historical Financials'!G27/'Historical Financials'!G25 -> 0.19260968 | H26: ='Historical Financials'!H27/'Historical Financials'!H25 -> 0.21892179 | I26: ='Historical Financials'!I27/'Historical Financials'!I25 -> 0.28041181 | J26: ='Historical Financials'!J27/'Historical Financials'!J25 -> 0.22910661 | ... L26: ='Historical Financials'!L27/'Historical Financials'!L25 -> 0.18727125
B29: Working Capital Schedule
B30: Particulars | C30: 44621 | D30: 44256 | E30: 43891 | F30: 43525 | G30: 43160 | H30: 42795 | I30: 42430 | J30: 42064 | K30: 41699 | L30: 41334
B31: CURRENT ASSETS
B32: Current Investments | C32: 844.31 | D32: 657.17 | E32: 637.18 | F32: 481.31 | G32: 855.76 | H32: 681.79 | I32: 154.55 | J32: 151.38 | K32: 102 | L32: 0
B33: Inventories | C33: 2129.85 | D33: 1716.25 | E33: 1703.12 | F33: 1558.59 | G33: 1577.72 | H33: 1412.5 | I33: 1306.98 | J33: 1071.71 | K33: 1082.13 | L33: 1047.09
B34: Trade Receivables | C34: 1116.32 | D34: 1004.5 | E34: 1157.25 | F34: 1292.9 | G34: 1245.5 | H34: 1028.74 | I34: 1118.01 | J34: 804.58 | K34: 711.28 | L34: 728.76
B35: Cash And Cash Equivalents | C35: 1107.77 | D35: 672.21 | E35: 770.16 | F35: 894.72 | G35: 960.21 | H35: 912.66 | I35: 753.79 | J35: 894.22 | K35: 704.79 | L35: 868.78
B36: OtherCurrentAssets | C36: 488.97 | D36: 417.64 | E36: 537.36 | F36: 457.16 | G36: 525.6 | H36: 338.75 | I36: 154.9 | J36: 7.58 | K36: 1.08 | L36: 2.91
B37: Total Current Assets | C37: =SUM(C32:C36) -> 5687.22 | D37: =SUM(D32:D36) -> 4467.77 | E37: =SUM(E32:E36) -> 4805.07 | F37: =SUM(F32:F36) -> 4684.68 | G37: =SUM(G32:G36) -> 5164.79 | H37: =SUM(H32:H36) -> 4374.44 | I37: =SUM(I32:I36) -> 3488.23 | J37: =SUM(J32:J36) -> 2929.47 | ... L37: =SUM(L32:L36) -> 2647.54
B38: CURRENT LIABILITIES
B39: Short Term Borrowings | C39: 1226.81 | D39: 279.41 | E39: 518.7 | F39: 270.94 | G39: 140.51 | H39: 232.55 | I39: 181.89 | J39: 146.66 | K39: 111.48 | L39: 82.44
B40: Trade Payables | C40: 2163.06 | D40: 2159.64 | E40: 2480.49 | F40: 2539.88 | G40: 2356.85 | H40: 1723.9 | I40: 1485.08 | J40: 1086.94 | K40: 1234.42 | L40: 1034.81
B41: Other Current Liabilities | C41: 505.53 | D41: 1624.24 | E41: 1491.41 | F41: 1030.11 | G41: 1619.62 | H41: 1332.77 | I41: 977.24 | J41: 1281.31 | K41: 1298.15 | L41: 1103.32
B42: Short Term Provisions | C42: 76.21 | D42: 72.4 | E42: 55.96 | F42: 50.85 | G42: 47.82 | H42: 58.14 | I42: 70.39 | J42: 97.68 | K42: 55.89 | L42: 58.52
B43: Total Current Liabilities | C43: =SUM(C39:C42) -> 3971.61 | D43: =SUM(D39:D42) -> 4135.69 | E43: =SUM(E39:E42) -> 4546.56 | F43: =SUM(F39:F42) -> 3891.78 | G43: =SUM(G39:G42) -> 4164.8 | H43: =SUM(H39:H42) -> 3347.36 | I43: =SUM(I39:I42) -> 2714.6 | J43: =SUM(J39:J42) -> 2612.59 | ... L43: =SUM(L39:L42) -> 2279.09
B44: Net Working Capital | C44: =C37-C43 -> 1715.61 | D44: =D37-D43 -> 332.08 | E44: =E37-E43 -> 258.51 | F44: =F37-F43 -> 792.9 | G44: =G37-G43 -> 999.99 | H44: =H37-H43 -> 1027.08 | I44: =I37-I43 -> 773.63 | J44: =J37-J43 -> 316.88 | ... L44: =L37-L43 -> 368.45
B45: Change in working Capital | C45: =C44-D44 -> 1383.53 | D45: =D44-E44 -> 73.57 | E45: =E44-F44 -> -534.39 | F45: =F44-G44 -> -207.09 | G45: =G44-H44 -> -27.09 | H45: =H44-I44 -> 253.45 | I45: =I44-J44 -> 456.75 | J45: =J44-K44 -> 415.54 | K45: =K44-L44 -> -467.11
B46: Change in NWC as % of revenue | C46: =C45/'Historical Financials'!C13 -> 0.11187987 | D46: =D45/'Historical Financials'!D13 -> 0.0066305025 | E46: =E45/'Historical Financials'!E13 -> -0.05331584 | F46: =F45/'Historical Financials'!F13 -> -0.019868369 | G46: =G45/'Historical Financials'!G13 -> -0.0027223887 | H46: =H45/'Historical Financials'!H13 -> 0.027126651 | I46: =I45/'Historical Financials'!I13 -> 0.053686155 | J46: =J45/'Historical Financials'!J13 -> 0.049658993 | K46: =K45/'Historical Financials'!K13 -> -0.060939685

Sheet Free Cash Flows
Q2: ASSUMPTIONS
D3: 1 | E3: 2 | F3: 3 | G3: 4 | H3: 5 | I3: =H3+1 -> 6 | J3: =I3+1 -> 7 | K3: =J3+1 -> 8 | L3: =K3+1 -> 9 | M3: =L3+1 -> 10 | N3: 11
C4: Base (FY22) | D4: FY23E | E4: FY24E | F4: FY25E | G4: FY26E | H4: FY27E | I4: FY28E | J4: FY29E | K4: FY30E | L4: FY31E | M4: FY32E | N4: Terminal Year | Q4: Particulars | R4: Percentage
B5: Particulars | Q5: Average CapEx as % of Opening PPE Balance | R5: =AVERAGE(Schedules!C12:L12) -> 0.16464888
B6: Revenue growth rate | C6: =('Historical Financials'!C9/'Historical Financials'!D9)-1 -> 0.1132232 | D6: =$R$7 -> 0.1022216 | E6: =D6*(1-0.05) -> 0.097110524 | F6: =E6*(1-0.05) -> 0.092254998 | G6: =F6*(1-0.05) -> 0.087642248 | H6: =G6*(1-0.05) -> 0.083260136 | I6: =H6*(1-0.05) -> 0.079097129 | J6: =I6*(1-0.05) -> 0.075142273 | K6: =J6*(1-0.05) -> 0.071385159 | L6: =K6*(1-0.05) -> 0.067815901 | M6: =L6*(1-0.05) -> 0.064425106 | Q6: Average D%A as % of Opening PPE Balance | R6: =AVERAGE(Schedules!C11:L11) -> 0.17120333
B7: Revenue from sales | C7: ='Historical Financials'!C13 -> 12366.21 | D7: =C7*(1+D6) -> 13630.304 | E7: =D7*(1+E6) -> 14953.95 | F7: =E7*(1+F6) -> 16333.526 | G7: =F7*(1+G6) -> 17765.033 | H7: =G7*(1+H6) -> 19244.152 | I7: =H7*(1+I6) -> 20766.31 | J7: =I7*(1+J6) -> 22326.737 | K7: =J7*(1+K6) -> 23920.535 | ... M7: =L7*(1+M6) -> 27188.321 | Q7: Average Revenue Growth | R7: =AVERAGE(Schedules!C24:L24)+0.026 -> 0.1022216
B8: Operating Margin | C8: =Schedules!C25 -> 0.39521729 | D8: =$R$8 -> 0.42572389 | E8: =$R$8 -> 0.42572389 | F8: =$R$8 -> 0.42572389 | G8: =$R$8 -> 0.42572389 | H8: =$R$8 -> 0.42572389 | I8: =$R$8 -> 0.42572389 | J8: =$R$8 -> 0.42572389 | K8: =$R$8 -> 0.42572389 | ... M8: =$R$8 -> 0.42572389 | Q8: Average Operating Margin | R8: =AVERAGE(Schedules!C25:L25) -> 0.42572389
B9: Operating income | C9: =C7*C8 -> 4887.34 | D9: =D7*D8 -> 5802.746 | E9: =E7*E8 -> 6366.2537 | F9: =F7*F8 -> 6953.5724 | G9: =G7*G8 -> 7562.9992 | H9: =H7*H8 -> 8192.6955 | I9: =I7*I8 -> 8840.7142 | J9: =J7*J8 -> 9505.0256 | ... M9: =M7*M8 -> 11574.718 | Q9: Average Change in NWC % of revenue | R9: =AVERAGE(Schedules!C46:D46) -> 0.059255188
B10: Tax rate | C10: =Schedules!C26 -> 0.1843683 | D10: =$R$10 -> 0.21149995 | E10: =$R$10 -> 0.21149995 | F10: =$R$10 -> 0.21149995 | G10: =$R$10 -> 0.21149995 | H10: =$R$10 -> 0.21149995 | I10: =$R$10 -> 0.21149995 | J10: =$R$10 -> 0.21149995 | K10: =$R$10 -> 0.21149995 | ... M10: =$R$10 -> 0.21149995 | Q10: Average Tax Rate | R10: =AVERAGE(Schedules!C26:L26) -> 0.21149995
B11: EBIT (1-T) | C11: =C9*(1-C10) -> 3986.2694 | D11: =D9*(1-D10) -> 4575.4655 | E11: =E9*(1-E10) -> 5019.7914 | F11: =F9*(1-F10) -> 5482.8922 | G11: =G9*(1-G10) -> 5963.4252 | H11: =H9*(1-H10) -> 6459.9408 | I11: =I9*(1-I10) -> 6970.9036 | J11: =J9*(1-J10) -> 7494.7131 | ... M11: =M9*(1-M10) -> 9126.6655
B12: Opening Balance of PPE | C12: =Schedules!C6 -> 1210.22 | D12: =Schedules!C17 -> 1274.91 | E12: =Schedules!D17 -> 1462.9017 | F12: =Schedules!E17 -> 1673.2209 | G12: =Schedules!F17 -> 1907.7635 | H12: =Schedules!G17 -> 2168.4974 | I12: =Schedules!H17 -> 2457.4566 | J12: =Schedules!I17 -> 2776.7339 | K12: =Schedules!J17 -> 3128.4734 | ... M12: =Schedules!L17 -> 3938.1188
B13: Depreciation | C13: =C12*$R$6 -> 207.1937 | D13: =D12*$R$6 -> 218.26884 | E13: =E12*$R$6 -> 250.45365 | F13: =F12*$R$6 -> 286.461 | G13: =G12*$R$6 -> 326.61547 | H13: =H12*$R$6 -> 371.25398 | I13: =I12*$R$6 -> 420.72476 | J13: =J12*$R$6 -> 475.3861 | ... M13: =M12*$R$6 -> 674.21907
B14: (Less) Capital Expenditure | C14: =Schedules!C9-Schedules!C6+Schedules!C7 -> 95.67 | D14: =C12*$R$5 -> 199.26137 | E14: =D12*$R$5 -> 209.9125 | F14: =E12*$R$5 -> 240.86513 | G14: =F12*$R$5 -> 275.49395 | H14: =G12*$R$5 -> 314.11112 | I14: =H12*$R$5 -> 357.04067 | J14: =I12*$R$5 -> 404.61747 | K14: =J12*$R$5 -> 457.18613 | ... M14: =L12*$R$5 -> 578.71803
B15: (Less) Change in Working Capital | C15: =Schedules!C45 -> 1383.53 | D15: =D7*$R$9 -> 807.66621 | E15: =E7*$R$9 -> 886.0991 | F15: =F7*$R$9 -> 967.84617 | G15: =G7*$R$9 -> 1052.6704 | H15: =H7*$R$9 -> 1140.3159 | I15: =I7*$R$9 -> 1230.5116 | J15: =J7*$R$9 -> 1322.975 | K15: =K7*$R$9 -> 1417.4158 | ... M15: =M7*$R$9 -> 1611.049
B16: FCF | C16: =C11+C13-C14-C15 -> 2714.2631 | D16: =D11+D13-D14-D15 -> 3786.8068 | E16: =E11+E13-E14-E15 -> 4174.2334 | F16: =F11+F13-F14-F15 -> 4560.6419 | G16: =G11+G13-G14-G15 -> 4961.8763 | H16: =H11+H13-H14-H15 -> 5376.7678 | I16: =I11+I13-I14-I15 -> 5804.0761 | J16: =J11+J13-J14-J15 -> 6242.5067 | ... M16: =M11+M13-M14-M15 -> 7611.1175 | N16: =(M16*(1+M6))/(DCF!R26-DCF!R10) -> 219627.53
C20: =SUM(D17:N17) -> 0

Sheet DCF
C2: DISCOUNTED CASH FLOW MODEL
Q3: ASSUMPTIONS
Q4: Cost of Debt
B5: ` | C5: ='Free Cash Flows'!D4 -> FY23E | D5: ='Free Cash Flows'!E4 -> FY24E | E5: ='Free Cash Flows'!F4 -> FY25E | F5: ='Free Cash Flows'!G4 -> FY26E | G5: ='Free Cash Flows'!H4 -> FY27E | H5: ='Free Cash Flows'!I4 -> FY28E | I5: ='Free Cash Flows'!J4 -> FY29E | J5: ='Free Cash Flows'!K4 -> FY30E | ... M5: ='Free Cash Flows'!N4 -> Terminal Year | Q5: Interest Expenses | R5: 103.6
B6: Free Cash Flows | C6: ='Free Cash Flows'!D16 -> 3786.8068 | D6: ='Free Cash Flows'!E16 -> 4174.2334 | E6: ='Free Cash Flows'!F16 -> 4560.6419 | F6: ='Free Cash Flows'!G16 -> 4961.8763 | G6: ='Free Cash Flows'!H16 -> 5376.7678 | H6: ='Free Cash Flows'!I16 -> 5804.0761 | I6: ='Free Cash Flows'!J16 -> 6242.5067 | J6: ='Free Cash Flows'!K16 -> 6690.7275 | ... M6: ='Free Cash Flows'!N16 -> 219627.53 | Q6: Total Debt | R6: 1608
Q7: Cost Of Debt | R7: =R5/R6 -> 0.064427861
B8: Projection Year | C8: 1 | D8: 2 | E8: 3 | F8: 4 | G8: 5 | H8: 6 | I8: 7 | J8: 8 | K8: 9 | L8: 10 | M8: 11 | Q8: Effective Tax Rate | R8: 0.2554
B9: Present Value of Free Cash Flow | C9: =C6/(1+$R$26)^C8 -> 3438.4492 | D9: =D6/(1+$R$26)^D8 -> 3441.5626 | E9: =E6/(1+$R$26)^E8 -> 3414.2427 | F9: =F6/(1+$R$26)^F8 -> 3372.9028 | G9: =G6/(1+$R$26)^G8 -> 3318.7049 | H9: =H6/(1+$R$26)^H8 -> 3252.8941 | I9: =I6/(1+$R$26)^I8 -> 3176.7667 | J9: =J6/(1+$R$26)^J8 -> 3091.6415 | ... M9: =M6/(1+$R$26)^M8 -> 75975.046
Q10: Terminal Growth Rate | R10: ='Free Cash Flows'!M6 -> 0.064425106
B12: Implied Share Price Calculation | Q12: Cost of Equity
B13: Sum of PV of CF | C13: =SUM(C9:L9) -> 32405.632 | Q13: Risk Free Rate | R13: 0.0731
B14: PV of Terminal Value | C14: =M9 -> 75975.046
B15: Enterprice Value | C15: =C13+C14 -> 108380.68 | Q15: Beta | R15: 0.64
B16: add: Cash | C16: ='Historical Financials'!O43 -> 1107.77 | Q16: Market Premium | R16: 0.045
B17: (less) Debt | C17: =DCF!R6 -> 1608 | Q17: Cost of Equity | R17: =(R13+R15*R16) -> 0.1019
B18: (less) Minority Interest | C18: ='Historical Financials'!O13 -> 0 | G18: FINAL CALL | H18: UNDERVALUED
B19: Equity Value | C19: =C15+C16-C17 -> 107880.45
B20: No. of Shares Outstanding | C20: 102 | Q20: Weight of Debt and Equity
B21: Implied Share Price | C21: =C19/C20 -> 1057.6514 | Q21: Total Debt | R21: 1608 | S21: =R21/R23 -> 0.015681073
Q22: Market Cap | R22: 100936 | S22: =R22/R23 -> 0.98431893
Q23: Total | R23: =R21+R22 -> 102544
B24: Market Price of the Share | C24: 987.15
Q26: WACC | R26: =(R7*S21)+(R17*S22) -> 0.1013124

Sheet Historical Financials
B3: Consolidated Profit & Loss account | C3: ------------------- in Rs. Cr. ------------------- | N3: Consolidated Balance Sheet | O3: ------------------- in Rs. Cr. ------------------- | Z3: Consolidated Cash Flow | AA3: ------------------- in Rs. Cr. -------------------
C4: 44621 | D4: 44256 | E4: 43891 | F4: 43525 | G4: 43160 | H4: 42795 | I4: 42430 | J4: 42064 | K4: 41699 | L4: 41334 | O4: Mar 22 | P4: 44256 | Q4: 43891 | R4: 43525 | S4: 43160 | T4: Mar 17 | U4: 42430 | V4: 42064 | W4: 41699 | X4: 41334 | AA4: Mar '22 | AB4: Mar '21 | AC4: Mar '20 | AD4: Mar '19 | AE4: Mar '18 | AF4: Mar '17 | AG4: Mar '16 | AH4: Mar '15 | AI4: Mar '14 | AJ4: Mar '13
B6: INCOME | N6: EQUITIES AND LIABILITIES | AA6: 12 mths | AB6: 12 mths | AC6: 12 mths | AD6: 12 mths | AE6: 12 mths | AF6: 12 mths | AG6: 12 mths | AH6: 12 mths | AI6: 12 mths | AJ6: 12 mths
B7: Revenue From Operations [Gross] | C7: 12174.22 | D7: 10936.01 | E7: 9826.51 | F7: 10221.07 | G7: 9861.74 | H7: 9583.7 | I7: 8742.4 | J7: 8515.34 | K7: 7803.1 | L7: 6598.9 | N7: SHAREHOLDER'S FUNDS
B8: Less: Excise/Sevice Tax/Other Levies | C8: 0 | D8: 0 | E8: 0 | F8: 0 | G8: 93.72 | H8: 340.89 | I8: 329.18 | J8: 273.14 | K8: 220.53 | L8: 208.11 | N8: Equity Share Capital | O8: 102.26 | P8: 102.25 | Q8: 102.23 | R8: 102.22 | S8: 68.13 | T8: 34.06 | U8: 34.05 | V8: 34.04 | W8: 34.04 | X8: 34.03 | Z8: Net Profit Before Tax | AA8: 2155.26 | AB8: 2080.36 | AC8: 1760.4 | AD8: 1832.77 | AE8: 1859.32 | AF8: 1687.05 | AG8: 1500.18 | AH8: 1265.89 | AI8: 1023.8 | AJ8: 895.71
B9: Revenue From Operations [Net] | C9: 12174.22 | D9: 10936.01 | E9: 9826.51 | F9: 10221.07 | G9: 9768.02 | H9: 9242.81 | I9: 8413.22 | J9: 8242.2 | K9: 7582.57 | L9: 6390.79 | N9: Total Share Capital | O9: 102.26 | P9: 102.25 | Q9: 102.23 | R9: 102.22 | S9: 68.13 | T9: 34.06 | U9: 34.05 | V9: 34.04 | W9: 34.04 | X9: 34.03 | Z9: Net Cash From Operating Activities | AA9: 1450.57 | AB9: 2029.63 | AC9: 1588.11 | AD9: 1728.85 | AE9: 1723.35 | AF9: 1860.22 | AG9: 847.37 | AH9: 1004.57 | AI9: 1128.64 | AJ9: 828.27
B10: Other Operating Revenues | C10: 102.28 | D10: 92.61 | E10: 84.29 | F10: 93.27 | G10: 75.25 | H10: 25.1 | I10: 10.66 | J10: 34.16 | K10: 19.84 | L10: 16.65 | N10: Reserves and Surplus | O10: 11453.67 | P10: 9336.65 | Q10: 7796.13 | R10: 7164.7 | S10: 6190.18 | T10: 5267.89 | U10: 4232.91 | V10: 4276.65 | W10: 3741.36 | X10: 3279.01 | Z10: Net Cash (used in)/from | AA10: -864.23 | AB10: -315.5 | AC10: -533.26 | AD10: 251.55 | AE10: -339.83 | AF10: -2169.76 | AG10: -602.25 | AH10: -1213.81 | AI10: -494.78 | AJ10: -815.65
B11: Total Operating Revenues | C11: 12276.5 | D11: 11028.62 | E11: 9910.8 | F11: 10314.34 | G11: 9843.27 | H11: 9267.91 | I11: 8423.88 | J11: 8276.36 | K11: 7602.41 | L11: 6407.44 | N11: Total Reserves and Surplus | O11: 11453.67 | P11: 9336.65 | Q11: 7796.13 | R11: 7164.7 | S11: 6190.18 | T11: 5267.89 | U11: 4232.91 | V11: 4276.65 | W11: 3741.36 | X11: 3279.01 | Z11: Investing Activities
B12: Other Income | C12: 89.71 | D12: 67.07 | E12: 112.3 | F12: 108.76 | G12: 107.55 | H12: 75.3 | I12: 83.9 | J12: 91.51 | K12: 62.71 | L12: 67.78 | N12: Total Shareholders Funds | O12: 11555.93 | P12: 9438.9 | Q12: 7898.36 | R12: 7266.92 | S12: 6258.31 | T12: 5301.95 | U12: 4266.96 | V12: 4310.69 | W12: 3775.4 | X12: 3313.04 | Z12: Net Cash (used in)/from Financing Activities | AA12: -379.52 | AB12: -1816.22 | AC12: -1295.33 | AD12: -2038.73 | AE12: -1384.01 | AF12: 664.65 | AG12: -202.47 | AH12: -12.04 | AI12: -633.26 | AJ12: 281.68
B13: Total Revenue | C13: 12366.21 | D13: 11095.69 | E13: 10023.1 | F13: 10423.1 | G13: 9950.82 | H13: 9343.21 | I13: 8507.78 | J13: 8367.87 | K13: 7665.12 | L13: 6475.22 | N13: Minority Interest | O13: 0 | P13: 0 | Q13: 0 | R13: 0 | S13: 0 | T13: 0 | U13: 10.02 | V13: 162.04 | W13: 225.1 | X13: 209.51 | Z13: Net (decrease)/increase In Cash and Cash Equivalents | AA13: 226.79 | AB13: -77.19 | AC13: -255.5 | AD13: -38.14 | AE13: 0.39 | AF13: 299.88 | AG13: 42.65 | AH13: -221.24 | AI13: 1.14 | AJ13: 294.3
B14: EXPENSES | N14: NON-CURRENT LIABILITIES | Z14: Opening Cash & Cash Equivalents | AA14: 524.13 | AB14: 600.96 | AC14: 856.46 | AD14: 894.6 | AE14: 894.21 | AF14: 594.33 | AG14: 535.59 | AH14: 625.21 | AI14: 624.46 | AJ14: 451.34
B15: Cost Of Materials Consumed | C15: 5782.98 | D15: 4606.76 | E15: 4121.75 | F15: 4062.43 | G15: 3646.23 | H15: 3801.91 | I15: 3457.78 | J15: 3370.75 | K15: 2967.62 | L15: 2655.98 | N15: Long Term Borrowings | O15: 380.85 | P15: 480.11 | Q15: 2145.04 | R15: 2604.78 | S15: 2380.32 | T15: 3108.25 | U15: 2449.03 | V15: 2023.03 | W15: 1590.25 | X15: 1866.15 | Z15: Closing Cash & Cash Equivalents | AA15: 750.92 | AB15: 523.77 | AC15: 600.96 | AD15: 856.46 | AE15: 894.6 | AF15: 894.21 | AG15: 578.24 | AH15: 403.97 | AI15: 625.6 | AJ15: 745.64
B16: Purchase Of Stock-In Trade | C16: 353.65 | D16: 365.01 | E16: 313.08 | F16: 337.36 | G16: 572.13 | H16: 463.94 | I16: 501.36 | J16: 435.73 | K16: 536.68 | L16: 451.03 | N16: Deferred Tax Liabilities [Net] | O16: 51.94 | P16: 39.03 | Q16: 76.73 | R16: 76.53 | S16: 304.72 | T16: 286.11 | U16: 211.17 | V16: 3.13 | W16: 4.65 | X16: 5.96
B17: Changes In Inventories Of FG,WIP And Stock-In Trade | C17: -61.54 | D17: -42.35 | E17: -173.15 | F17: 154.54 | G17: 56 | H17: -133.33 | I17: -91.9 | J17: 35.04 | K17: 50.38 | L17: -155.89 | N17: Other Long Term Liabilities | O17: 66.73 | P17: 74.37 | Q17: 173.34 | R17: 221.82 | S17: 756.32 | T17: 912.29 | U17: 67.24 | V17: 4.12 | W17: 5.62 | X17: 5.14
B18: Employee Benefit Expenses | C18: 1104.14 | D18: 1123.34 | E18: 1018.82 | F18: 1068.41 | G18: 1057.41 | H18: 988.46 | I18: 944.13 | J18: 776.95 | K18: 748.87 | L18: 590.68 | N18: Long Term Provisions | O18: 107 | P18: 114.72 | Q18: 116.98 | R18: 108.25 | S18: 98.24 | T18: 80.57 | U18: 34.71 | V18: 26.34 | W18: 23.78 | X18: 22.14
B19: Finance Costs | C19: 110.16 | D19: 126.63 | E19: 217.41 | F19: 224.25 | G19: 160.74 | H19: 145.22 | I19: 119.01 | J19: 100.15 | K19: 107.37 | L19: 77.45 | N19: Total Non-Current Liabilities | O19: 606.52 | P19: 708.23 | Q19: 2512.09 | R19: 3011.38 | S19: 3539.6 | T19: 4387.22 | U19: 2762.15 | V19: 2056.62 | W19: 1624.3 | X19: 1899.39
B20: Depreciation And Amortisation Expenses | C20: 209.93 | D20: 203.85 | E20: 197.28 | F20: 169.98 | G20: 155.68 | H20: 141.57 | I20: 100.63 | J20: 90.78 | K20: 81.85 | L20: 77 | N20: CURRENT LIABILITIES
B21: Other Expenses | C21: 2702.16 | D21: 2587.61 | E21: 2487.27 | F21: 2573.99 | G21: 2444.39 | H21: 2249.21 | I21: 1976.69 | J21: 2292.58 | K21: 2148.55 | L21: 1883.26 | N21: Short Term Borrowings | O21: 1226.81 | P21: 279.41 | Q21: 518.7 | R21: 270.94 | S21: 140.51 | T21: 232.55 | U21: 181.89 | V21: 146.66 | W21: 111.48 | X21: 82.44
B22: Total Expenses | C22: 10201.48 | D22: 8970.85 | E22: 8182.46 | F22: 8590.96 | G22: 8092.58 | H22: 7656.98 | I22: 7007.7 | J22: 7101.98 | K22: 6641.32 | L22: 5579.51 | N22: Trade Payables | O22: 2163.06 | P22: 2159.64 | Q22: 2480.49 | R22: 2539.88 | S22: 2356.85 | T22: 1723.9 | U22: 1485.08 | V22: 1086.94 | W22: 1234.42 | X22: 1034.81
B23: Profit/Loss Before Exceptional, ExtraOrdinary Items And Tax | C23: 2164.73 | D23: 2124.84 | E23: 1840.64 | F23: 1832.14 | G23: 1858.24 | H23: 1686.23 | I23: 1500.08 | J23: 1265.89 | K23: 1023.8 | L23: 895.71 | N23: Other Current Liabilities | O23: 505.53 | P23: 1624.24 | Q23: 1491.41 | R23: 1030.11 | S23: 1619.62 | T23: 1332.77 | U23: 977.24 | V23: 1281.31 | W23: 1298.15 | X23: 1103.32
B24: Exceptional Items | C24: -9.75 | D24: -44.47 | E24: -81.05 | F24: 252.56 | G24: 179.56 | H24: 0.08 | I24: -333.51 | J24: -17.17 | K24: 5.87 | L24: 128.9 | N24: Short Term Provisions | O24: 76.21 | P24: 72.4 | Q24: 55.96 | R24: 50.85 | S24: 47.82 | T24: 58.14 | U24: 70.39 | V24: 97.68 | W24: 55.89 | X24: 58.52
B25: Profit/Loss Before Tax | C25: 2154.98 | D25: 2080.37 | E25: 1759.59 | F25: 2084.7 | G25: 2037.8 | H25: 1686.31 | I25: 1166.57 | J25: 1248.72 | K25: 1029.67 | L25: 1024.61 | N25: Total Current Liabilities | O25: 3971.61 | P25: 4135.69 | Q25: 4546.56 | R25: 3891.78 | S25: 4164.8 | T25: 3347.36 | U25: 2714.6 | V25: 2612.59 | W25: 2699.94 | X25: 2279.09
B26: Tax Expenses-Continued Operations | N26: Total Capital And Liabilities | O26: 16134.06 | P26: 14282.82 | Q26: 14957.01 | R26: 14170.08 | S26: 13962.71 | T26: 13036.53 | U26: 9753.73 | V26: 9141.94 | W26: 8324.74 | X26: 7701.03
B27: Current Tax | C27: 397.31 | D27: 408.14 | E27: 378.66 | F27: 417.9 | G27: 392.5 | H27: 369.17 | I27: 327.12 | J27: 286.09 | K27: 216.71 | L27: 191.88 | N27: ASSETS
B28: Deferred Tax | C28: -25.44 | D28: -48.6 | E28: -114.84 | F28: -674.1 | G28: 12.2 | H28: 9.99 | I28: 8.93 | J28: -13.8 | K28: -6.34 | L28: -12.7 | N28: NON-CURRENT ASSETS
B29: Total Tax Expenses | C29: 371.87 | D29: 359.54 | E29: 263.82 | F29: -256.2 | G29: 404.7 | H29: 379.16 | I29: 336.05 | J29: 272.29 | K29: 210.37 | L29: 179.18 | N29: Tangible Assets | O29: 1373.36 | P29: 1301.35 | Q29: 1256.92 | R29: 1192.29 | S29: 1066.36 | T29: 942.58 | U29: 847.09 | V29: 558.11 | W29: 522.42 | X29: 502.13
B30: Profit/Loss After Tax And Before ExtraOrdinary Items | C30: 1783.11 | D30: 1720.83 | E30: 1495.77 | F30: 2340.9 | G30: 1633.1 | H30: 1307.15 | I30: 830.52 | J30: 976.43 | K30: 819.3 | L30: 845.43 | N30: Intangible Assets | O30: 2469.15 | P30: 2473.57 | Q30: 2635.16 | R30: 2559.94 | S30: 2529.77 | T30: 2477.75 | U30: 941.96 | V30: 948.79 | W30: 1046.49 | X30: 1085.48
B31: Profit/Loss From Continuing Operations | C31: 1783.11 | D31: 1720.83 | E31: 1495.77 | F31: 2340.9 | G31: 1633.1 | H31: 1307.15 | I31: 830.52 | J31: 976.43 | K31: 819.3 | L31: 845.43 | N31: Capital Work-In-Progress | O31: 114.75 | P31: 52.97 | Q31: 55.67 | R31: 50.9 | S31: 82.08 | T31: 95.11 | U31: 41.49 | V31: 224.61 | W31: 167.07 | X31: 140.85
B32: Profit/Loss For The Period | C32: 1783.11 | D32: 1720.83 | E32: 1495.77 | F32: 2340.9 | G32: 1633.1 | H32: 1307.15 | I32: 830.52 | J32: 976.43 | K32: 819.3 | L32: 845.43 | N32: Intangible Assets Under Development | O32: 1.69 | P32: 4.46 | Q32: 1.37 | R32: 1.16 | S32: 1.8 | T32: 2.32 | U32: 2.17 | V32: 0 | W32: 0 | X32: 0
B33: Share Of Profit/Loss Of Associates | C33: 0.28 | D33: -0.01 | E33: 0.81 | F33: 0.63 | G33: 1.08 | H33: -3.89 | I33: -3.01 | J33: -69.35 | K33: -59.52 | L33: -49.33 | N33: Fixed Assets | O33: 3958.95 | P33: 3832.35 | Q33: 3949.12 | R33: 3804.29 | S33: 3680.01 | T33: 3517.76 | U33: 1832.71 | V33: 1731.51 | W33: 1735.98 | X33: 1728.46
B34: Consolidated Profit/Loss After MI And Associates | C34: 1783.39 | D34: 1720.82 | E34: 1496.58 | F34: 2341.53 | G34: 1634.18 | H34: 1304.08 | I34: 827.61 | J34: 907.12 | K34: 759.73 | L34: 796.1 | N34: Non-Current Investments | O34: 171.12 | P34: 21.93 | Q34: 34.8 | R34: 34.67 | S34: 141.52 | T34: 251.75 | U34: 34.95 | V34: 34.31 | W34: 34.27 | X34: 0
B35: OTHER ADDITIONAL INFORMATION | N35: Deferred Tax Assets [Net] | O35: 731.51 | P35: 676.79 | Q35: 646.79 | R35: 549.32 | S35: 100.04 | T35: 96.28 | U35: 74.99 | V35: 34.34 | W35: 24.97 | X35: 19.98
B36: EARNINGS PER SHARE | N36: Long Term Loans And Advances | O36: 0.03 | P36: 21.78 | Q36: 22.63 | R36: 18.77 | S36: 18.87 | T36: 19.28 | U36: 15.45 | V36: 208.11 | W36: 157.37 | X36: 194.75
B37: Basic EPS (Rs.) | C37: 17 | D37: 17 | E37: 15 | F37: 23 | G37: 24 | H37: 19 | I37: 24 | J37: 27 | K37: 22 | L37: 23 | N37: Other Non-Current Assets | O37: 208.39 | P37: 127.71 | Q37: 156.01 | R37: 156.59 | S37: 135.72 | T37: 110.85 | U37: 160.47 | V37: 0.06 | W37: 1.44 | X37: 1.02
B38: Diluted EPS (Rs.) | C38: 17 | D38: 17 | E38: 15 | F38: 23 | G38: 24 | H38: 19 | I38: 24 | J38: 27 | K38: 22 | L38: 23 | N38: Total Non-Current Assets | O38: 10446.79 | P38: 9810.41 | Q38: 10148.67 | R38: 9481.67 | S38: 8795.03 | T38: 8658.48 | U38: 6260.93 | V38: 6052.38 | W38: 5506.48 | X38: 4852.66
B39: DIVIDEND AND DIVIDEND PERCENTAGE | N39: CURRENT ASSETS
B40: Equity Share Dividend | C40: 0 | D40: 0 | E40: 817.82 | F40: 1226.52 | G40: 613.12 | H40: 195.78 | I40: 187.27 | J40: 187.24 | K40: 178.7 | L40: 170.16 | N40: Current Investments | O40: 844.31 | P40: 657.17 | Q40: 637.18 | R40: 481.31 | S40: 855.76 | T40: 681.79 | U40: 154.55 | V40: 151.38 | W40: 102 | X40: 0
N41: Inventories | O41: 2129.85 | P41: 1716.25 | Q41: 1703.12 | R41: 1558.59 | S41: 1577.72 | T41: 1412.5 | U41: 1306.98 | V41: 1071.71 | W41: 1082.13 | X41: 1047.09
N42: Trade Receivables | O42: 1116.32 | P42: 1004.5 | Q42: 1157.25 | R42: 1292.9 | S42: 1245.5 | T42: 1028.74 | U42: 1118.01 | V42: 804.58 | W42: 711.28 | X42: 728.76
N43: Cash And Cash Equivalents | O43: 1107.77 | P43: 672.21 | Q43: 770.16 | R43: 894.72 | S43: 960.21 | T43: 912.66 | U43: 753.79 | V43: 894.22 | W43: 704.79 | X43: 868.78
...

Sheet Notes
B3: 1 | C3: Capital Expenditure includes disposabled assets
B4: 2 | C4: Tax Rate: New provision inserted in the income tax act (Sept 2019) with effect from fiscal year 2019-20, allows any domestic company to pay income tax at the rate of 25.17% subject to condition they will not avail any incentive or exemptions.
B5: 3 | C5: FCF = EBIT * (1 - Tax Rate) + Depreciation & Amortization - Change in Working Capital - Capital Ependiture
B6: 4 | C6: Other Expenses include non-operating expenses like Rent, Stationary, etc
B7: 5 | C7: Opening and Closing Balances already account for D%A (Taken from Annual Reports)
B8: 6 | C8: add 3% due to future plans as mentioned in annual reports, further decreases by 2.5%
